<?xml version="1.0" encoding="UTF-8"?>
<robot xmlns:xacro="http://wiki.ros.org/xacro">
  <xacro:include filename="$(find steering_chassis_description)/urdf/common/inertials.xacro" />
  <xacro:include filename="$(find steering_chassis_description)/urdf/common/materials.xacro" />

  <xacro:property name="R" value="0.2" />
  <xacro:property name="A" value="0.3" />

  <xacro:macro name="steering_wheel" params= "prefix index parent  *origin">
    <link name="${prefix}wheel${index}_base_link">
      <visual>
        <origin xyz="0 0 0" rpy="0 0 0"/>
        <geometry>
          <box size="${A} ${A} 0.1"/>
        </geometry>
        <material name="black"/>
      </visual>
      <collision>
        <origin xyz="0 0 0" rpy="0 0 0"/>
        <geometry>
          <box size="${A} ${A} 0.1"/>
        </geometry>
      </collision>
      <inertial>
        <origin xyz="0 0 0" rpy="0 0 0"/>
        <mass value="0.1"/>
        <inertia ixx="0.0001" ixy="0.0" ixz="0.0" iyy="0.0001" iyz="0.0" izz="0.0001"/>
      </inertial>
    </link>
    <link name="${prefix}wheel${index}_link1">
      <!-- Default inertial for Gazebo - copy and edit block from 'common.xacro'
           to get more realistic behavior-->
      <xacro:default_inertial/>
      <visual>
        <origin xyz="0 0 0" rpy="0 0 0" />
        <geometry>
          <cylinder length="0.05" radius="0.15" />
          <!--           <mesh filename="package://steering_chassis_description/meshes/steering_chassis/visual/link2.dae" /> -->
        </geometry>
        <material name="grey"/>
      </visual>
      <collision>
        <origin xyz="0 0 0" rpy="0 0 0" />
        <geometry>
          <cylinder length="0.05" radius="0.15" />
          <!--           <mesh filename="package://steering_chassis_description/meshes/steering_chassis/collision/link2.stl" /> -->
        </geometry>
      </collision>
    </link>
    <link name="${prefix}wheel${index}_link2">
      <!-- Default inertial for Gazebo - copy and edit block from 'common.xacro'
           to get more realistic behavior-->
      <xacro:default_inertial/>
      <visual>
        <origin xyz="0 0 0" rpy="${pi/2} 0 0" />
        <geometry>
          <cylinder length="0.1" radius="${R}" />
          <!--           <mesh filename="package://steering_chassis_description/meshes/steering_chassis/visual/link2.dae" /> -->
        </geometry>
        <material name="grey"/>
      </visual>
      <collision>
        <origin xyz="0 0 0" rpy="${pi/2} 0 0" />
        <geometry>
          <cylinder length="0.1" radius="${R}" />
          <!--           <mesh filename="package://steering_chassis_description/meshes/steering_chassis/collision/link2.stl" /> -->
        </geometry>
      </collision>
    </link>
    <!-- JOINTS -->
    <!-- base_joint fixes base_link to the environment -->
    <joint name="${prefix}wheel${index}_base_joint" type="fixed">
      <xacro:insert_block name="origin" />
      <parent link="${parent}" />
      <child link="${prefix}wheel${index}_base_link" />
    </joint>
    <!-- joint 1 -->
    <joint name="${prefix}wheel${index}_joint1" type="continuous">
      <origin xyz="0 0 0" rpy="0 0 0" />
      <parent link="${prefix}wheel${index}_base_link" />
      <child link="${prefix}wheel${index}_link1" />
      <axis xyz="0 0 1" />
    </joint>
    <joint name="${prefix}wheel${index}_joint2" type="continuous">
      <origin xyz="0 0 0" rpy="0 0 0" />
      <parent link="${prefix}wheel${index}_link1" />
      <child link="${prefix}wheel${index}_link2" />
      <axis xyz="0 1 0" />
    </joint>
  </xacro:macro>

</robot>